<?xml version="1.0"?>
<robot name="pandt_robot">
	<link name="world"/>

	<link name="base_link">
		<visual>
			<geometry>
				<cylinder length="0.00001" radius="0.5"/>
			</geometry>
			<material name="black">
				<color rgba="255 255 255 1"/>
			</material>
			<origin rpy="0 0 0" xyz="0 0 0.025"/>
		</visual>
	</link>
	<joint name="fixed" type="fixed">
		<parent link="world"/>
		<child link="base_link"/>
	</joint>

	<link name="pan_body">
		<visual>
			<geometry>
				<mesh filename="package://pandt_description/mesh/base_pat.stl"
					scale="0.02 0.02 0.02"/>
			</geometry>
			<material name="blue">
				<color rgba="0 0 1 1"/>
			</material>
			<origin rpy = "0 0 0" xyz="0 0 0.05"/>
		</visual>
	</link>
	<joint name="Pan" type="continuous">
		<parent link="base_link"/>
		<child link= "pan_body"/>
		<origin rpy="0 0 0" xyz="0 0 0"/>
		<axis xyz="0 0 1"/>
	</joint>


</robot>